------ SCHEDULING TEST 0 -------------------------------------------
./os sched_0
	Loaded a process at input/proc/s0, PID: 1
Time slot   0
	CPU 0: Dispatched process  1
Time slot   1
Time slot   2
	CPU 0: Put process  1 to run queue
	CPU 0: Dispatched process  1
Time slot   3
	Loaded a process at input/proc/s1, PID: 2
Time slot   4
	CPU 0: Put process  1 to run queue
	CPU 0: Dispatched process  2
Time slot   5
Time slot   6
	CPU 0: Put process  2 to run queue
	CPU 0: Dispatched process  2
Time slot   7
Time slot   8
	CPU 0: Put process  2 to run queue
	CPU 0: Dispatched process  1
Time slot   9
Time slot  10
	CPU 0: Put process  1 to run queue
	CPU 0: Dispatched process  2
Time slot  11
Time slot  12
	CPU 0: Put process  2 to run queue
	CPU 0: Dispatched process  1
Time slot  13
Time slot  14
	CPU 0: Put process  1 to run queue
	CPU 0: Dispatched process  2
Time slot  15
	CPU 0: Processed  2 has finished
	CPU 0: Dispatched process  1
Time slot  16
Time slot  17
	CPU 0: Put process  1 to run queue
	CPU 0: Dispatched process  1
Time slot  18
Time slot  19
	CPU 0: Put process  1 to run queue
	CPU 0: Dispatched process  1
Time slot  20
Time slot  21
	CPU 0: Put process  1 to run queue
	CPU 0: Dispatched process  1
Time slot  22
	CPU 0: Processed  1 has finished
	CPU 0 stopped

MEMORY CONTENT: 
NOTE: Read file output/sched_0 to verify your result
------ SCHEDULING TEST 1 -------------------------------------------
./os sched_1
	Loaded a process at input/proc/s0, PID: 1
Time slot   0
	CPU 0: Dispatched process  1
Time slot   1
Time slot   2
	CPU 0: Put process  1 to run queue
	CPU 0: Dispatched process  1
Time slot   3
	Loaded a process at input/proc/s1, PID: 2
Time slot   4
	CPU 0: Put process  1 to run queue
	CPU 0: Dispatched process  2
Time slot   5
	Loaded a process at input/proc/s2, PID: 3
Time slot   6
	Loaded a process at input/proc/s3, PID: 4
	CPU 0: Put process  2 to run queue
	CPU 0: Dispatched process  3
Time slot   7
Time slot   8
	CPU 0: Put process  3 to run queue
	CPU 0: Dispatched process  4
Time slot   9
Time slot  10
	CPU 0: Put process  4 to run queue
	CPU 0: Dispatched process  2
Time slot  11
Time slot  12
	CPU 0: Put process  2 to run queue
	CPU 0: Dispatched process  3
Time slot  13
Time slot  14
	CPU 0: Put process  3 to run queue
	CPU 0: Dispatched process  1
Time slot  15
Time slot  16
	CPU 0: Put process  1 to run queue
	CPU 0: Dispatched process  4
Time slot  17
Time slot  18
	CPU 0: Put process  4 to run queue
	CPU 0: Dispatched process  2
Time slot  19
Time slot  20
	CPU 0: Put process  2 to run queue
	CPU 0: Dispatched process  3
Time slot  21
Time slot  22
	CPU 0: Put process  3 to run queue
	CPU 0: Dispatched process  1
Time slot  23
Time slot  24
	CPU 0: Put process  1 to run queue
	CPU 0: Dispatched process  4
Time slot  25
Time slot  26
	CPU 0: Put process  4 to run queue
	CPU 0: Dispatched process  2
Time slot  27
	CPU 0: Processed  2 has finished
	CPU 0: Dispatched process  3
Time slot  28
Time slot  29
	CPU 0: Put process  3 to run queue
	CPU 0: Dispatched process  1
Time slot  30
Time slot  31
	CPU 0: Put process  1 to run queue
	CPU 0: Dispatched process  4
Time slot  32
Time slot  33
	CPU 0: Put process  4 to run queue
	CPU 0: Dispatched process  3
Time slot  34
Time slot  35
	CPU 0: Put process  3 to run queue
	CPU 0: Dispatched process  1
Time slot  36
Time slot  37
	CPU 0: Put process  1 to run queue
	CPU 0: Dispatched process  4
Time slot  38
Time slot  39
	CPU 0: Put process  4 to run queue
	CPU 0: Dispatched process  3
Time slot  40
Time slot  41
	CPU 0: Processed  3 has finished
	CPU 0: Dispatched process  1
Time slot  42
Time slot  43
	CPU 0: Put process  1 to run queue
	CPU 0: Dispatched process  4
Time slot  44
	CPU 0: Processed  4 has finished
	CPU 0: Dispatched process  1
Time slot  45
	CPU 0: Processed  1 has finished
	CPU 0 stopped

MEMORY CONTENT: 
NOTE: Read file output/sched_1 to verify your result

